<?xml version="1.0" ?>
<robot name="simple_gripper">
  <link name="base_link">
    <inertial>
      <mass value="0.3"/>
      <inertia ixx="0.0002" iyy="0.0002" izz="0.0002" ixy="0" ixz="0" iyz="0"/>
    </inertial>
    <visual>
      <geometry>
        <box size="0.04 0.04 0.08"/>
      </geometry>
      <material name="gray">
        <color rgba="0.6 0.6 0.6 1"/>
      </material>
    </visual>
    <collision>
      <geometry>
        <box size="0.04 0.04 0.08"/>
      </geometry>
    </collision>
  </link>

  <link name="left_finger">
    <inertial>
      <mass value="0.05"/>
      <inertia ixx="0.00001" iyy="0.00001" izz="0.00001" ixy="0" ixz="0" iyz="0"/>
    </inertial>
    <visual>
      <geometry>
        <box size="0.02 0.01 0.05"/>
      </geometry>
      <material name="blue">
        <color rgba="0.2 0.2 0.8 1"/>
      </material>
    </visual>
    <collision>
      <geometry>
        <box size="0.02 0.01 0.05"/>
      </geometry>
    </collision>
  </link>

  <link name="right_finger">
    <inertial>
      <mass value="0.05"/>
      <inertia ixx="0.00001" iyy="0.00001" izz="0.00001" ixy="0" ixz="0" iyz="0"/>
    </inertial>
    <visual>
      <geometry>
        <box size="0.02 0.01 0.05"/>
      </geometry>
      <material name="blue">
        <color rgba="0.2 0.2 0.8 1"/>
      </material>
    </visual>
    <collision>
      <geometry>
        <box size="0.02 0.01 0.05"/>
      </geometry>
    </collision>
  </link>

  <joint name="left_finger_joint" type="prismatic">
    <parent link="base_link"/>
    <child link="left_finger"/>
    <origin xyz="-0.03 0 0" rpy="0 0 0"/>
    <axis xyz="1 0 0"/>
    <limit lower="0" upper="0.05" effort="10" velocity="1"/>
  </joint>

  <joint name="right_finger_joint" type="prismatic">
    <parent link="base_link"/>
    <child link="right_finger"/>
    <origin xyz="0.03 0 0" rpy="0 0 0"/>
    <axis xyz="1 0 0"/>
    <limit lower="-0.05" upper="0" effort="10" velocity="1"/>
  </joint>
</robot>
